Workbook

Sheet Übung1
A1: ID | B1: Nachfolger | E1: D | G1: 45775 | H1: 45776 | I1: 45777 | J1: 45778 | K1: 45779 | L1: 45780 | M1: 45781 | N1: 45782 | O1: 45783 | P1: 45784 | Q1: 45785 | R1: 45786 | S1: 45787 | T1: 45788 | U1: 45789 | V1: 45790 | W1: 45791 | X1: 45792 | Y1: 45793 | Z1: 45794 | AA1: 45795 | AB1: 45796 | AC1: 45797 | AD1: 45798 | AE1: 45799 | AF1: 45800 | AG1: 45801 | AH1: 45802 | AI1: 45803 | AJ1: 45804 | AK1: 45805 | AL1: 45806 | AM1: 45807 | AN1: 45808 | AO1: 45809 | AP1: 45810 | AQ1: 45811 | AR1: 45812 | AS1: 45813 | AT1: 45814 | AU1: 45815 | AV1: 45816 | AW1: 45817 | AX1: 45818 | AY1: 45819 | AZ1: 45820 | BA1: 45821 | BB1: 45822 | BC1: 45823 | BD1: 45824 | BE1: 45825 | BF1: 45826 | BG1: 45827 | BH1: 45828 | BI1: 45829 | BJ1: 45830 | BK1: 45831 | BL1: 45832 | BM1: 45833 | BN1: 45834 | BO1: 45835 | BP1: 45836 | BQ1: 45837
A2: A | B2: B | C2: C | E2: 2
A3: B | B3: D | E3: 8
A4: C | B4: E | C4: F | E4: 8
A5: D | B5: G | E5: 6
A6: E | B6: H | E6: 8
A7: F | B7: I | E7: 8
A8: G | B8: J | E8: 5
A9: H | B9: K | E9: 6
A10: I | B10: K | E10: 5
A11: J | B11: L | E11: 8
A12: K | B12: L | E12: 2
A13: L | E13: 4
A15: 0 | C15: 2 | F15: 2 | H15: 10 | K15: 10 | M15: 16 | P15: 16 | R15: 21 | U15: 21 | W15: 29 | Z15: 29 | AB15: 33
A16: A | F16: B | K16: D | P16: G | U16: J | Z16: L | AD16: kritischer Pfad
A17: 2 | B17: 0 | C17: 0 | F17: 8 | G17: 0 | H17: 0 | K17: 6 | L17: 0 | M17: 0 | P17: 5 | Q17: 0 | R17: 0 | U17: 8 | V17: 0 | W17: 0 | Z17: 4 | AA17: 0 | AB17: 0
A18: 0 | C18: 2 | F18: 2 | H18: 10 | K18: 10 | M18: 16 | P18: 16 | R18: 21 | U18: 21 | W18: 29 | Z18: 29 | AB18: 33
F21: 2 | H21: 10 | K21: 10 | M21: 18 | P21: 18 | R21: 24 | U21: 24 | W21: 26
F22: C | K22: E | P22: H | U22: K
F23: 8 | G23: 3 | H23: 0 | K23: 8 | L23: 3 | M23: 0 | P23: 6 | Q23: 3 | R23: 0 | U23: 2 | V23: 3 | W23: 3
F24: 5 | H24: 13 | K24: 13 | M24: 21 | P24: 21 | R24: 27 | U24: 27 | W24: 29
K27: 10 | M27: 18 | P27: 18 | R27: 23
K28: F | P28: I
K29: 8 | L29: 4 | M29: 0 | P29: 5 | Q29: 4 | R29: 1
K30: 14 | M30: 22 | P30: 22 | R30: 27
A35: Anfangszeit | C35: Endzeit
A36: FAZ | C36: FEZ | D36: Frühester | H36: FEZ = FAZ + D
A37: ID | H37: FAZ = größste FEZ (Vorgänger)
A38: D | B38: GP | C38: FP | D38: Puffer | H38: SEZ = kleinste SAZ (Nachfolger)
A39: SAZ | C39: SEZ | D39: Spätester | H39: SAZ = SEZ - D
I40: GP = SAZ-FAZ = SEZ-FEZ
H41: FP = kleinste FAZ (Nachfolger) – FEZ
B55: FAZ | D55: FEZ
B56: ID | F56: Kritischer Pfad
B57: D | C57: GP | D57: FP
B58: SAZ | D58: SEZ
B60: FAZ | C60: Frühester Anfangszeitpunkt
B61: SAZ | C61: Spätester Anfangszeitpunkt
B62: FEZ | C62: Frühester Endzeitpunkt
B63: SEZ | C63: Spätester Endzeitpunkt
...

Sheet Übung2
A1: ID | B1: Vorgänger | E1: D | G1: 45775 | H1: 45776 | I1: 45777 | J1: 45778 | K1: 45779 | L1: 45780 | M1: 45781 | N1: 45782 | O1: 45783 | P1: 45784 | Q1: 45785 | R1: 45786 | S1: 45787 | T1: 45788 | U1: 45789 | V1: 45790 | W1: 45791 | X1: 45792 | Y1: 45793 | Z1: 45794 | AA1: 45795 | AB1: 45796 | AC1: 45797 | AD1: 45798 | AE1: 45799 | AF1: 45800 | AG1: 45801 | AH1: 45802 | AI1: 45803 | AJ1: 45804 | AK1: 45805 | AL1: 45806 | AM1: 45807 | AN1: 45808 | AO1: 45809 | AP1: 45810 | AQ1: 45811 | AR1: 45812 | AS1: 45813 | AT1: 45814 | AU1: 45815 | AV1: 45816 | AW1: 45817 | AX1: 45818 | AY1: 45819 | AZ1: 45820 | BA1: 45821 | BB1: 45822 | BC1: 45823 | BD1: 45824 | BE1: 45825 | BF1: 45826 | BG1: 45827 | BH1: 45828 | BI1: 45829 | BJ1: 45830 | BK1: 45831 | BL1: 45832
A2: A | E2: 6
A4: B | B4: A | E4: 7
A5: C | B5: A | E5: 7
A6: D | B6: B | E6: 4
A8: E | B8: C | E8: 4
A9: F | B9: C | E9: 5
A10: G | B10: D | E10: 3
A11: Auftragegeberpräsi
A12: H | B12: E | C12: F | E12: 6
A13: I | B13: G | C13: H | E13: 2
A15: 0 | C15: 6 | F15: 6 | H15: 13 | K15: 13 | M15: 17 | P15: 17 | R15: 20 | U15: 24 | W15: 26
A16: A | F16: B | K16: D | P16: G | U16: I
A17: 6 | B17: 0 | C17: 0 | F17: 7 | G17: 4 | H17: 0 | K17: 4 | L17: 4 | M17: 0 | P17: 3 | Q17: 4 | R17: 4 | U17: 2 | V17: 0 | W17: 0
A18: 0 | C18: 6 | F18: 10 | H18: 17 | K18: 17 | M18: 21 | P18: 21 | R18: 24 | U18: 24 | W18: 26
F21: 6 | H21: 13 | K21: 13 | M21: 17 | P21: 18 | R21: 24
F22: C | K22: E | P22: H
F23: 7 | G23: 0 | H23: 0 | K23: 4 | L23: 1 | M23: 1 | P23: 6 | Q23: 0 | R23: 0
F24: 6 | H24: 13 | K24: 14 | M24: 18 | P24: 18 | R24: 24
K27: 13 | M27: 18
K28: F
K29: 5 | L29: 0 | M29: 0
K30: 13 | M30: 18

Sheet Übung3
A1: ID | B1: Nachfolger | E1: PT | F1: P | G1: K% | H1: D | I1: =Übung2!G1 -> 45775 | J1: =Übung2!H1 -> 45776 | K1: =Übung2!I1 -> 45777 | L1: =Übung2!J1 -> 45778 | M1: =Übung2!K1 -> 45779 | N1: =Übung2!L1 -> 45780 | O1: =Übung2!M1 -> 45781 | P1: =Übung2!N1 -> 45782 | ... DI1: =Übung2!DG1 -> 0
A2: A | B2: B | C2: C | D2: D | E2: 15 | F2: 3 | G2: 1 | H2: =ROUNDUP(E2/(F2*G2),0) -> 5
A3: B | B3: G | E3: 6 | F3: 1 | G3: 0.5 | H3: =ROUNDUP(E3/(F3*G3),0) -> 12
A4: C | B4: E | E4: 14 | F4: 1 | G4: 1.5 | H4: =ROUNDUP(E4/(F4*G4),0) -> 10
A5: D | B5: F | E5: 6 | F5: 1 | G5: 1 | H5: =ROUNDUP(E5/(F5*G5),0) -> 6
A6: E | B6: H | E6: 15 | F6: 1 | G6: 1.75 | H6: =ROUNDUP(E6/(F6*G6),0) -> 9
A7: F | B7: H | E7: 14 | F7: 1 | G7: 0.75 | H7: =ROUNDUP(E7/(F7*G7),0) -> 19
A8: G | B8: I | E8: 7 | F8: 1 | G8: 0.5 | H8: =ROUNDUP(E8/(F8*G8),0) -> 14
A9: H | B9: I | E9: 15 | F9: 1 | G9: 1.5 | H9: =ROUNDUP(E9/(F9*G9),0) -> 10
A10: I | E10: 4 | F10: 3 | G10: 1 | H10: =ROUNDUP(E10/(F10*G10),0) -> 2
A12: 0 | C12: =A12+A14 -> 5 | F12: =$C$12 -> 5 | H12: =F12+F14 -> 17 | K12: =H12 -> 17 | M12: =K12+K14 -> 31 | U12: =MAX(M12,R18) -> 40 | W12: =U12+U14 -> 42
A13: A | F13: B | K13: G | U13: I
A14: =VLOOKUP(A13,$A$2:$H$10,8) -> 5 | B14: =C15-C12 -> 0 | C14: =MIN(F12,F18,F24)-C12 -> 0 | F14: =VLOOKUP(F13,$A$2:$H$10,8) -> 12 | G14: =H15-H12 -> 9 | H14: =K12-H12 -> 0 | K14: =VLOOKUP(K13,$A$2:$H$10,8) -> 14 | L14: =M15-M12 -> 9 | M14: =U12-M12 -> 9 | U14: =VLOOKUP(U13,$A$2:$H$10,8) -> 2 | V14: =W15-W12 -> 0 | W14: 0
A15: =C15-A14 -> 0 | C15: =MIN(F15,F21,F27) -> 5 | F15: =H15-F14 -> 14 | H15: =K15 -> 26 | K15: =M15-K14 -> 26 | M15: =U12 -> 40 | U15: =W15-U14 -> 40 | W15: =W12 -> 42
F18: =$C$12 -> 5 | H18: =F18+F20 -> 15 | K18: =H18 -> 15 | M18: =K18+K20 -> 24 | P18: =MAX(M18,M24) -> 30 | R18: =P18+P20 -> 40
F19: C | K19: E | P19: H
F20: =VLOOKUP(F19,$A$2:$H$10,8) -> 10 | G20: =H21-H18 -> 6 | H20: =K18-H18 -> 0 | K20: =VLOOKUP(K19,$A$2:$H$10,8) -> 9 | L20: =M21-M18 -> 6 | M20: =P18-M18 -> 6 | P20: =VLOOKUP(P19,$A$2:$H$10,8) -> 10 | Q20: =R21-R18 -> 0 | R20: =U12-R18 -> 0
F21: =H21-F20 -> 11 | H21: =K21 -> 21 | K21: =M21-K20 -> 21 | M21: =P21 -> 30 | P21: =R21-P20 -> 30 | R21: =U15 -> 40
F24: =$C$12 -> 5 | H24: =F24+F26 -> 11 | K24: =H24 -> 11 | M24: =K24+K26 -> 30
F25: D | K25: F
F26: =VLOOKUP(F25,$A$2:$H$10,8) -> 6 | G26: =H27-H24 -> 0 | H26: =K24-H24 -> 0 | K26: =VLOOKUP(K25,$A$2:$H$10,8) -> 19 | L26: =M27-M24 -> 0 | M26: =P18-M24 -> 0
F27: =H27-F26 -> 5 | H27: =K27 -> 11 | K27: =M27-K26 -> 11 | M27: =P21 -> 30

Sheet Übung 4
A1: ID | B1: Vorgänger | E1: D | G1: 45775 | H1: 45776 | I1: 45777 | J1: 45778 | K1: 45779 | L1: 45780 | M1: 45781 | N1: 45782 | O1: 45783 | P1: 45784 | Q1: 45785 | R1: 45786 | S1: 45787 | T1: 45788 | U1: 45789 | V1: 45790 | W1: 45791 | X1: 45792 | Y1: 45793 | Z1: 45794 | AA1: 45795
A2: A | E2: 3
A3: B | B3: A | E3: 1
A4: C | B4: A | E4: 1
A5: D | B5: A | E5: 2
A6: E | B6: C | E6: 1
A7: F | B7: D | E7: 2
A8: G | B8: B | E8: 1
A9: H | B9: E | C9: F | E9: 1
A10: I | B10: G | E10: 1
A11: J | B11: H | E11: 1
A12: K | B12: I | C12: J | E12: 3
A14: 0 | C14: 3 | F14: 3 | H14: 4 | K14: 4 | M14: 5 | P14: 5 | R14: 6 | Z14: 9 | AB14: 12
A15: A | F15: B | K15: G | P15: I | Z15: I
A16: 3 | F16: 1 | K16: 1 | P16: 1 | Z16: 3 | AA16: 0 | AB16: 0
R17: 9 | Z17: 9 | AB17: 12
F20: 3 | H20: 4 | K20: 4 | M20: 5 | P20: 7 | R20: 8 | U20: 8 | W20: 9
F21: C | K21: E | P21: H | U21: J
F22: 1 | G22: 2 | H22: 0 | K22: 1 | L22: 2 | M22: 2 | P22: 1 | Q22: 0 | R22: 0 | U22: 1 | V22: 0 | W22: 0
F23: 3 | H23: 6 | K23: 6 | M23: 7 | P23: 7 | R23: 8 | U23: 8 | W23: 9
F26: 3 | H26: 5 | K26: 5 | M26: 7
F27: D | K27: F
F28: 2 | G28: 0 | H28: 0 | K28: 2 | L28: 0 | M28: 0
F29: 3 | H29: 5 | K29: 5 | M29: 7

Sheet Feiertage
A1: Datum | B1: Feiertag
A2: 45297 | B2: Heilige Drei Könige | C2: KW 01 | E2: Ba-Wü, Bay, Sa-An | F2: 45413 | G2: 45414
A3: 45359 | B3: Internationaler Frauentag | C3: KW 10 | D3: verlängertes Wochenende | E3: B, MV
A4: 45380 | B4: Karfreitag | C4: KW 13 | D4: verlängertes Wochenende | E4: bundesweit
A5: 45383 | B5: Ostermontag | C5: KW 14 | D5: verlängertes Wochenende | E5: bundesweit
A6: 45413 | B6: Tag der Arbeit | C6: KW 18 | E6: bundesweit
A7: 45421 | B7: Christi Himmelfahrt | C7: KW 19 | D7: Brückentag möglich | E7: bundesweit
A8: 45432 | B8: Pfingstmontag | C8: KW 21 | D8: verlängertes Wochenende | E8: bundesweit
A9: 45442 | B9: Fronleichnam | C9: KW 22 | D9: Brückentag möglich | E9: BaWü, Bay, Hes, NRW, Rh-Pf, Sa-La
A10: 45519 | B10: Mariä Himmelfahrt | C10: KW 33 | D10: Brückentag möglich | E10: Bay, Sa-La
A11: 45555 | B11: Weltkindertag | C11: KW 38 | D11: verlängertes Wochenende | E11: Thü
A12: 45568 | B12: Tag der Deutschen Einheit | C12: KW 40 | D12: Brückentag möglich | E12: bundesweit
A13: 45596 | B13: Reformationstag | C13: KW 44 | D13: Brückentag möglich | E13: BB, HH, MV, Sa, Sa-An, S-H, Thü
A14: 45597 | B14: Allerheiligen | C14: KW 44 | D14: verlängertes Wochenende | E14: BaWü, Bay, NRW, Rh-Pf, Sa-La
A15: 45616 | B15: Buß- und Bettag | C15: KW 47 | E15: Sa.
A16: 45651 | B16: 1. Weihnachtstag | C16: KW 52 | D16: bundesweit
A17: 45652 | B17: 2. Weihnachtstag | C17: KW 52 | D17: Brückentag möglich | E17: bundesweit
